{"blocks": [{"x": 99, "y": 80, "z": 99, "block": "minecraft:spruce_stairs[facing=east,half=bottom]"}, {"x": 107, "y": 80, "z": 99, "block": "minecraft:spruce_stairs[facing=west,half=bottom]"}, {"x": 99, "y": 81, "z": 99, "block": "minecraft:spruce_stairs[facing=east,half=bottom]"}, {"x": 107, "y": 81, "z": 99, "block": "minecraft:spruce_stairs[facing=west,half=bottom]"}, {"x": 99, "y": 80, "z": 100, "block": "minecraft:spruce_stairs[facing=east,half=bottom]"}, {"x": 107, "y": 80, "z": 100, "block": "minecraft:spruce_stairs[facing=west,half=bottom]"}, {"x": 99, "y": 80, "z": 101, "block": "minecraft:spruce_stairs[facing=east,half=bottom]"}, {"x": 107, "y": 80, "z": 101, "block": "minecraft:spruce_stairs[facing=west,half=bottom]"}, {"x": 99, "y": 80, "z": 102, "block": "minecraft:spruce_stairs[facing=east,half=bottom]"}, {"x": 107, "y": 80, "z": 102, "block": "minecraft:spruce_stairs[facing=west,half=bottom]"}, {"x": 99, "y": 80, "z": 103, "block": "minecraft:spruce_stairs[facing=east,half=bottom]"}, {"x": 107, "y": 80, "z": 103, "block": "minecraft:spruce_stairs[facing=west,half=bottom]"}, {"x": 99, "y": 80, "z": 104, "block": "minecraft:spruce_stairs[facing=east,half=bottom]"}, {"x": 107, "y": 80, "z": 104, "block": "minecraft:spruce_stairs[facing=west,half=bottom]"}, {"x": 99, "y": 80, "z": 105, "block": "minecraft:spruce_stairs[facing=east,half=bottom]"}, {"x": 107, "y": 80, "z": 105, "block": "minecraft:spruce_stairs[facing=west,half=bottom]"}, {"x": 99, "y": 80, "z": 106, "block": "minecraft:spruce_stairs[facing=east,half=bottom]"}, {"x": 107, "y": 80, "z": 106, "block": "minecraft:spruce_stairs[facing=west,half=bottom]"}, {"x": 99, "y": 80, "z": 107, "block": "minecraft:spruce_stairs[facing=east,half=bottom]"}, {"x": 107, "y": 80, "z": 107, "block": "minecraft:spruce_stairs[facing=west,half=bottom]"}, {"x": 99, "y": 80, "z": 108, "block": "minecraft:spruce_stairs[facing=east,half=bottom]"}, {"x": 107, "y": 80, "z": 108, "block": "minecraft:spruce_stairs[facing=west,half=bottom]"}, {"x": 99, "y": 80, "z": 109, "block": "minecraft:spruce_stairs[facing=east,half=bottom]"}, {"x": 107, "y": 80, "z": 109, "block": "minecraft:spruce_stairs[facing=west,half=bottom]"}, {"x": 99, "y": 81, "z": 109, "block": "minecraft:spruce_stairs[facing=east,half=bottom]"}, {"x": 107, "y": 81, "z": 109, "block": "minecraft:spruce_stairs[facing=west,half=bottom]"}, {"x": 100, "y": 81, "z": 99, "block": "minecraft:spruce_stairs[facing=east,half=bottom]"}, {"x": 106, "y": 81, "z": 99, "block": "minecraft:spruce_stairs[facing=west,half=bottom]"}, {"x": 100, "y": 81, "z": 100, "block": "minecraft:spruce_stairs[facing=east,half=bottom]"}, {"x": 106, "y": 81, "z": 100, "block": "minecraft:spruce_stairs[facing=west,half=bottom]"}, {"x": 100, "y": 81, "z": 101, "block": "minecraft:spruce_stairs[facing=east,half=bottom]"}, {"x": 106, "y": 81, "z": 101, "block": "minecraft:spruce_stairs[facing=west,half=bottom]"}, {"x": 100, "y": 81, "z": 102, "block": "minecraft:spruce_stairs[facing=east,half=bottom]"}, {"x": 106, "y": 81, "z": 102, "block": "minecraft:spruce_stairs[facing=west,half=bottom]"}, {"x": 100, "y": 81, "z": 103, "block": "minecraft:spruce_stairs[facing=east,half=bottom]"}, {"x": 106, "y": 81, "z": 103, "block": "minecraft:spruce_stairs[facing=west,half=bottom]"}, {"x": 100, "y": 81, "z": 104, "block": "minecraft:spruce_stairs[facing=east,half=bottom]"}, {"x": 106, "y": 81, "z": 104, "block": "minecraft:spruce_stairs[facing=west,half=bottom]"}, {"x": 100, "y": 81, "z": 105, "block": "minecraft:spruce_stairs[facing=east,half=bottom]"}, {"x": 106, "y": 81, "z": 105, "block": "minecraft:spruce_stairs[facing=west,half=bottom]"}, {"x": 100, "y": 81, "z": 106, "block": "minecraft:spruce_stairs[facing=east,half=bottom]"}, {"x": 106, "y": 81, "z": 106, "block": "minecraft:spruce_stairs[facing=west,half=bottom]"}, {"x": 100, "y": 81, "z": 107, "block": "minecraft:spruce_stairs[facing=east,half=bottom]"}, {"x": 106, "y": 81, "z": 107, "block": "minecraft:spruce_stairs[facing=west,half=bottom]"}, {"x": 100, "y": 81, "z": 108, "block": "minecraft:spruce_stairs[facing=east,half=bottom]"}, {"x": 106, "y": 81, "z": 108, "block": "minecraft:spruce_stairs[facing=west,half=bottom]"}, {"x": 100, "y": 81, "z": 109, "block": "minecraft:spruce_stairs[facing=east,half=bottom]"}, {"x": 106, "y": 81, "z": 109, "block": "minecraft:spruce_stairs[facing=west,half=bottom]"}, {"x": 101, "y": 82, "z": 99, "block": "minecraft:spruce_stairs[facing=east,half=bottom]"}, {"x": 105, "y": 82, "z": 99, "block": "minecraft:spruce_stairs[facing=west,half=bottom]"}, {"x": 101, "y": 82, "z": 100, "block": "minecraft:spruce_stairs[facing=east,half=bottom]"}, {"x": 105, "y": 82, "z": 100, "block": "minecraft:spruce_stairs[facing=west,half=bottom]"}, {"x": 101, "y": 82, "z": 101, "block": "minecraft:spruce_stairs[facing=east,half=bottom]"}, {"x": 105, "y": 82, "z": 101, "block": "minecraft:spruce_stairs[facing=west,half=bottom]"}, {"x": 101, "y": 82, "z": 102, "block": "minecraft:spruce_stairs[facing=east,half=bottom]"}, {"x": 105, "y": 82, "z": 102, "block": "minecraft:spruce_stairs[facing=west,half=bottom]"}, {"x": 101, "y": 82, "z": 103, "block": "minecraft:spruce_stairs[facing=east,half=bottom]"}, {"x": 105, "y": 82, "z": 103, "block": "minecraft:spruce_stairs[facing=west,half=bottom]"}, {"x": 101, "y": 82, "z": 104, "block": "minecraft:spruce_stairs[facing=east,half=bottom]"}, {"x": 105, "y": 82, "z": 104, "block": "minecraft:spruce_stairs[facing=west,half=bottom]"}, {"x": 101, "y": 82, "z": 105, "block": "minecraft:spruce_stairs[facing=east,half=bottom]"}, {"x": 105, "y": 82, "z": 105, "block": "minecraft:spruce_stairs[facing=west,half=bottom]"}, {"x": 101, "y": 82, "z": 106, "block": "minecraft:spruce_stairs[facing=east,half=bottom]"}, {"x": 105, "y": 82, "z": 106, "block": "minecraft:spruce_stairs[facing=west,half=bottom]"}, {"x": 101, "y": 82, "z": 107, "block": "minecraft:spruce_stairs[facing=east,half=bottom]"}, {"x": 105, "y": 82, "z": 107, "block": "minecraft:spruce_stairs[facing=west,half=bottom]"}, {"x": 101, "y": 82, "z": 108, "block": "minecraft:spruce_stairs[facing=east,half=bottom]"}, {"x": 105, "y": 82, "z": 108, "block": "minecraft:spruce_stairs[facing=west,half=bottom]"}, {"x": 101, "y": 82, "z": 109, "block": "minecraft:spruce_stairs[facing=east,half=bottom]"}, {"x": 105, "y": 82, "z": 109, "block": "minecraft:spruce_stairs[facing=west,half=bottom]"}, {"x": 102, "y": 83, "z": 99, "block": "minecraft:spruce_stairs[facing=east,half=bottom]"}, {"x": 104, "y": 83, "z": 99, "block": "minecraft:spruce_stairs[facing=west,half=bottom]"}, {"x": 102, "y": 83, "z": 100, "block": "minecraft:spruce_stairs[facing=east,half=bottom]"}, {"x": 104, "y": 83, "z": 100, "block": "minecraft:spruce_stairs[facing=west,half=bottom]"}, {"x": 102, "y": 83, "z": 101, "block": "minecraft:spruce_stairs[facing=east,half=bottom]"}, {"x": 104, "y": 83, "z": 101, "block": "minecraft:spruce_stairs[facing=west,half=bottom]"}, {"x": 102, "y": 83, "z": 102, "block": "minecraft:spruce_stairs[facing=east,half=bottom]"}, {"x": 104, "y": 83, "z": 102, "block": "minecraft:spruce_stairs[facing=west,half=bottom]"}, {"x": 102, "y": 83, "z": 103, "block": "minecraft:spruce_stairs[facing=east,half=bottom]"}, {"x": 104, "y": 83, "z": 103, "block": "minecraft:spruce_stairs[facing=west,half=bottom]"}, {"x": 102, "y": 83, "z": 104, "block": "minecraft:spruce_stairs[facing=east,half=bottom]"}, {"x": 104, "y": 83, "z": 104, "block": "minecraft:spruce_stairs[facing=west,half=bottom]"}, {"x": 102, "y": 83, "z": 105, "block": "minecraft:spruce_stairs[facing=east,half=bottom]"}, {"x": 104, "y": 83, "z": 105, "block": "minecraft:spruce_stairs[facing=west,half=bottom]"}, {"x": 102, "y": 83, "z": 106, "block": "minecraft:spruce_stairs[facing=east,half=bottom]"}, {"x": 104, "y": 83, "z": 106, "block": "minecraft:spruce_stairs[facing=west,half=bottom]"}, {"x": 102, "y": 83, "z": 107, "block": "minecraft:spruce_stairs[facing=east,half=bottom]"}, {"x": 104, "y": 83, "z": 107, "block": "minecraft:spruce_stairs[facing=west,half=bottom]"}, {"x": 102, "y": 83, "z": 108, "block": "minecraft:spruce_stairs[facing=east,half=bottom]"}, {"x": 104, "y": 83, "z": 108, "block": "minecraft:spruce_stairs[facing=west,half=bottom]"}, {"x": 102, "y": 83, "z": 109, "block": "minecraft:spruce_stairs[facing=east,half=bottom]"}, {"x": 104, "y": 83, "z": 109, "block": "minecraft:spruce_stairs[facing=west,half=bottom]"}, {"x": 103, "y": 83, "z": 99, "block": "minecraft:spruce_planks"}, {"x": 103, "y": 84, "z": 99, "block": "minecraft:spruce_slab[type=top]"}, {"x": 103, "y": 83, "z": 100, "block": "minecraft:spruce_planks"}, {"x": 103, "y": 84, "z": 100, "block": "minecraft:spruce_slab[type=top]"}, {"x": 103, "y": 83, "z": 101, "block": "minecraft:spruce_planks"}, {"x": 103, "y": 84, "z": 101, "block": "minecraft:spruce_slab[type=top]"}, {"x": 103, "y": 83, "z": 102, "block": "minecraft:spruce_planks"}, {"x": 103, "y": 84, "z": 102, "block": "minecraft:spruce_slab[type=top]"}, {"x": 103, "y": 83, "z": 103, "block": "minecraft:spruce_planks"}, {"x": 103, "y": 84, "z": 103, "block": "minecraft:spruce_slab[type=top]"}, {"x": 103, "y": 83, "z": 104, "block": "minecraft:spruce_planks"}, {"x": 103, "y": 84, "z": 104, "block": "minecraft:spruce_slab[type=top]"}, {"x": 103, "y": 83, "z": 105, "block": "minecraft:spruce_planks"}, {"x": 103, "y": 84, "z": 105, "block": "minecraft:spruce_slab[type=top]"}, {"x": 103, "y": 83, "z": 106, "block": "minecraft:spruce_planks"}, {"x": 103, "y": 84, "z": 106, "block": "minecraft:spruce_slab[type=top]"}, {"x": 103, "y": 83, "z": 107, "block": "minecraft:spruce_planks"}, {"x": 103, "y": 84, "z": 107, "block": "minecraft:spruce_slab[type=top]"}, {"x": 103, "y": 83, "z": 108, "block": "minecraft:spruce_planks"}, {"x": 103, "y": 84, "z": 108, "block": "minecraft:spruce_slab[type=top]"}, {"x": 103, "y": 83, "z": 109, "block": "minecraft:spruce_planks"}, {"x": 103, "y": 84, "z": 109, "block": "minecraft:spruce_slab[type=top]"}]}
