{"blocks": [{"x": 99, "y": 80, "z": 99, "block": "minecraft:dark_oak_stairs[facing=south,half=bottom]"}, {"x": 99, "y": 80, "z": 109, "block": "minecraft:dark_oak_stairs[facing=north,half=bottom]"}, {"x": 99, "y": 81, "z": 99, "block": "minecraft:dark_oak_stairs[facing=south,half=bottom]"}, {"x": 99, "y": 81, "z": 109, "block": "minecraft:dark_oak_stairs[facing=north,half=bottom]"}, {"x": 100, "y": 80, "z": 99, "block": "minecraft:dark_oak_stairs[facing=south,half=bottom]"}, {"x": 100, "y": 80, "z": 109, "block": "minecraft:dark_oak_stairs[facing=north,half=bottom]"}, {"x": 101, "y": 80, "z": 99, "block": "minecraft:dark_oak_stairs[facing=south,half=bottom]"}, {"x": 101, "y": 80, "z": 109, "block": "minecraft:dark_oak_stairs[facing=north,half=bottom]"}, {"x": 102, "y": 80, "z": 99, "block": "minecraft:dark_oak_stairs[facing=south,half=bottom]"}, {"x": 102, "y": 80, "z": 109, "block": "minecraft:dark_oak_stairs[facing=north,half=bottom]"}, {"x": 103, "y": 80, "z": 99, "block": "minecraft:dark_oak_stairs[facing=south,half=bottom]"}, {"x": 103, "y": 80, "z": 109, "block": "minecraft:dark_oak_stairs[facing=north,half=bottom]"}, {"x": 104, "y": 80, "z": 99, "block": "minecraft:dark_oak_stairs[facing=south,half=bottom]"}, {"x": 104, "y": 80, "z": 109, "block": "minecraft:dark_oak_stairs[facing=north,half=bottom]"}, {"x": 105, "y": 80, "z": 99, "block": "minecraft:dark_oak_stairs[facing=south,half=bottom]"}, {"x": 105, "y": 80, "z": 109, "block": "minecraft:dark_oak_stairs[facing=north,half=bottom]"}, {"x": 106, "y": 80, "z": 99, "block": "minecraft:dark_oak_stairs[facing=south,half=bottom]"}, {"x": 106, "y": 80, "z": 109, "block": "minecraft:dark_oak_stairs[facing=north,half=bottom]"}, {"x": 107, "y": 80, "z": 99, "block": "minecraft:dark_oak_stairs[facing=south,half=bottom]"}, {"x": 107, "y": 80, "z": 109, "block": "minecraft:dark_oak_stairs[facing=north,half=bottom]"}, {"x": 107, "y": 81, "z": 99, "block": "minecraft:dark_oak_stairs[facing=south,half=bottom]"}, {"x": 107, "y": 81, "z": 109, "block": "minecraft:dark_oak_stairs[facing=north,half=bottom]"}, {"x": 100, "y": 80, "z": 100, "block": "minecraft:oak_planks"}, {"x": 100, "y": 80, "z": 101, "block": "minecraft:oak_planks"}, {"x": 100, "y": 80, "z": 102, "block": "minecraft:oak_planks"}, {"x": 100, "y": 80, "z": 103, "block": "minecraft:oak_planks"}, {"x": 100, "y": 80, "z": 104, "block": "minecraft:oak_planks"}, {"x": 100, "y": 80, "z": 105, "block": "minecraft:oak_planks"}, {"x": 100, "y": 80, "z": 106, "block": "minecraft:oak_planks"}, {"x": 100, "y": 80, "z": 107, "block": "minecraft:oak_planks"}, {"x": 100, "y": 80, "z": 108, "block": "minecraft:oak_planks"}, {"x": 106, "y": 80, "z": 100, "block": "minecraft:oak_planks"}, {"x": 106, "y": 80, "z": 101, "block": "minecraft:oak_planks"}, {"x": 106, "y": 80, "z": 102, "block": "minecraft:oak_planks"}, {"x": 106, "y": 80, "z": 103, "block": "minecraft:oak_planks"}, {"x": 106, "y": 80, "z": 104, "block": "minecraft:oak_planks"}, {"x": 106, "y": 80, "z": 105, "block": "minecraft:oak_planks"}, {"x": 106, "y": 80, "z": 106, "block": "minecraft:oak_planks"}, {"x": 106, "y": 80, "z": 107, "block": "minecraft:oak_planks"}, {"x": 106, "y": 80, "z": 108, "block": "minecraft:oak_planks"}, {"x": 99, "y": 81, "z": 100, "block": "minecraft:dark_oak_stairs[facing=south,half=bottom]"}, {"x": 99, "y": 81, "z": 108, "block": "minecraft:dark_oak_stairs[facing=north,half=bottom]"}, {"x": 100, "y": 81, "z": 100, "block": "minecraft:dark_oak_stairs[facing=south,half=bottom]"}, {"x": 100, "y": 81, "z": 108, "block": "minecraft:dark_oak_stairs[facing=north,half=bottom]"}, {"x": 101, "y": 81, "z": 100, "block": "minecraft:dark_oak_stairs[facing=south,half=bottom]"}, {"x": 101, "y": 81, "z": 108, "block": "minecraft:dark_oak_stairs[facing=north,half=bottom]"}, {"x": 102, "y": 81, "z": 100, "block": "minecraft:dark_oak_stairs[facing=south,half=bottom]"}, {"x": 102, "y": 81, "z": 108, "block": "minecraft:dark_oak_stairs[facing=north,half=bottom]"}, {"x": 103, "y": 81, "z": 100, "block": "minecraft:dark_oak_stairs[facing=south,half=bottom]"}, {"x": 103, "y": 81, "z": 108, "block": "minecraft:dark_oak_stairs[facing=north,half=bottom]"}, {"x": 104, "y": 81, "z": 100, "block": "minecraft:dark_oak_stairs[facing=south,half=bottom]"}, {"x": 104, "y": 81, "z": 108, "block": "minecraft:dark_oak_stairs[facing=north,half=bottom]"}, {"x": 105, "y": 81, "z": 100, "block": "minecraft:dark_oak_stairs[facing=south,half=bottom]"}, {"x": 105, "y": 81, "z": 108, "block": "minecraft:dark_oak_stairs[facing=north,half=bottom]"}, {"x": 106, "y": 81, "z": 100, "block": "minecraft:dark_oak_stairs[facing=south,half=bottom]"}, {"x": 106, "y": 81, "z": 108, "block": "minecraft:dark_oak_stairs[facing=north,half=bottom]"}, {"x": 107, "y": 81, "z": 100, "block": "minecraft:dark_oak_stairs[facing=south,half=bottom]"}, {"x": 107, "y": 81, "z": 108, "block": "minecraft:dark_oak_stairs[facing=north,half=bottom]"}, {"x": 100, "y": 81, "z": 101, "block": "minecraft:oak_planks"}, {"x": 100, "y": 81, "z": 102, "block": "minecraft:oak_planks"}, {"x": 100, "y": 81, "z": 103, "block": "minecraft:oak_planks"}, {"x": 100, "y": 81, "z": 104, "block": "minecraft:oak_planks"}, {"x": 100, "y": 81, "z": 105, "block": "minecraft:oak_planks"}, {"x": 100, "y": 81, "z": 106, "block": "minecraft:oak_planks"}, {"x": 100, "y": 81, "z": 107, "block": "minecraft:oak_planks"}, {"x": 106, "y": 81, "z": 101, "block": "minecraft:oak_planks"}, {"x": 106, "y": 81, "z": 102, "block": "minecraft:oak_planks"}, {"x": 106, "y": 81, "z": 103, "block": "minecraft:oak_planks"}, {"x": 106, "y": 81, "z": 104, "block": "minecraft:oak_planks"}, {"x": 106, "y": 81, "z": 105, "block": "minecraft:oak_planks"}, {"x": 106, "y": 81, "z": 106, "block": "minecraft:oak_planks"}, {"x": 106, "y": 81, "z": 107, "block": "minecraft:oak_planks"}, {"x": 99, "y": 82, "z": 101, "block": "minecraft:dark_oak_stairs[facing=south,half=bottom]"}, {"x": 99, "y": 82, "z": 107, "block": "minecraft:dark_oak_stairs[facing=north,half=bottom]"}, {"x": 100, "y": 82, "z": 101, "block": "minecraft:dark_oak_stairs[facing=south,half=bottom]"}, {"x": 100, "y": 82, "z": 107, "block": "minecraft:dark_oak_stairs[facing=north,half=bottom]"}, {"x": 101, "y": 82, "z": 101, "block": "minecraft:dark_oak_stairs[facing=south,half=bottom]"}, {"x": 101, "y": 82, "z": 107, "block": "minecraft:dark_oak_stairs[facing=north,half=bottom]"}, {"x": 102, "y": 82, "z": 101, "block": "minecraft:dark_oak_stairs[facing=south,half=bottom]"}, {"x": 102, "y": 82, "z": 107, "block": "minecraft:dark_oak_stairs[facing=north,half=bottom]"}, {"x": 103, "y": 82, "z": 101, "block": "minecraft:dark_oak_stairs[facing=south,half=bottom]"}, {"x": 103, "y": 82, "z": 107, "block": "minecraft:dark_oak_stairs[facing=north,half=bottom]"}, {"x": 104, "y": 82, "z": 101, "block": "minecraft:dark_oak_stairs[facing=south,half=bottom]"}, {"x": 104, "y": 82, "z": 107, "block": "minecraft:dark_oak_stairs[facing=north,half=bottom]"}, {"x": 105, "y": 82, "z": 101, "block": "minecraft:dark_oak_stairs[facing=south,half=bottom]"}, {"x": 105, "y": 82, "z": 107, "block": "minecraft:dark_oak_stairs[facing=north,half=bottom]"}, {"x": 106, "y": 82, "z": 101, "block": "minecraft:dark_oak_stairs[facing=south,half=bottom]"}, {"x": 106, "y": 82, "z": 107, "block": "minecraft:dark_oak_stairs[facing=north,half=bottom]"}, {"x": 107, "y": 82, "z": 101, "block": "minecraft:dark_oak_stairs[facing=south,half=bottom]"}, {"x": 107, "y": 82, "z": 107, "block": "minecraft:dark_oak_stairs[facing=north,half=bottom]"}, {"x": 100, "y": 82, "z": 102, "block": "minecraft:oak_planks"}, {"x": 100, "y": 82, "z": 103, "block": "minecraft:oak_planks"}, {"x": 100, "y": 82, "z": 104, "block": "minecraft:oak_planks"}, {"x": 100, "y": 82, "z": 105, "block": "minecraft:oak_planks"}, {"x": 100, "y": 82, "z": 106, "block": "minecraft:oak_planks"}, {"x": 106, "y": 82, "z": 102, "block": "minecraft:oak_planks"}, {"x": 106, "y": 82, "z": 103, "block": "minecraft:oak_planks"}, {"x": 106, "y": 82, "z": 104, "block": "minecraft:oak_planks"}, {"x": 106, "y": 82, "z": 105, "block": "minecraft:oak_planks"}, {"x": 106, "y": 82, "z": 106, "block": "minecraft:oak_planks"}, {"x": 99, "y": 83, "z": 102, "block": "minecraft:dark_oak_stairs[facing=south,half=bottom]"}, {"x": 99, "y": 83, "z": 106, "block": "minecraft:dark_oak_stairs[facing=north,half=bottom]"}, {"x": 100, "y": 83, "z": 102, "block": "minecraft:dark_oak_stairs[facing=south,half=bottom]"}, {"x": 100, "y": 83, "z": 106, "block": "minecraft:dark_oak_stairs[facing=north,half=bottom]"}, {"x": 101, "y": 83, "z": 102, "block": "minecraft:dark_oak_stairs[facing=south,half=bottom]"}, {"x": 101, "y": 83, "z": 106, "block": "minecraft:dark_oak_stairs[facing=north,half=bottom]"}, {"x": 102, "y": 83, "z": 102, "block": "minecraft:dark_oak_stairs[facing=south,half=bottom]"}, {"x": 102, "y": 83, "z": 106, "block": "minecraft:dark_oak_stairs[facing=north,half=bottom]"}, {"x": 103, "y": 83, "z": 102, "block": "minecraft:dark_oak_stairs[facing=south,half=bottom]"}, {"x": 103, "y": 83, "z": 106, "block": "minecraft:dark_oak_stairs[facing=north,half=bottom]"}, {"x": 104, "y": 83, "z": 102, "block": "minecraft:dark_oak_stairs[facing=south,half=bottom]"}, {"x": 104, "y": 83, "z": 106, "block": "minecraft:dark_oak_stairs[facing=north,half=bottom]"}, {"x": 105, "y": 83, "z": 102, "block": "minecraft:dark_oak_stairs[facing=south,half=bottom]"}, {"x": 105, "y": 83, "z": 106, "block": "minecraft:dark_oak_stairs[facing=north,half=bottom]"}, {"x": 106, "y": 83, "z": 102, "block": "minecraft:dark_oak_stairs[facing=south,half=bottom]"}, {"x": 106, "y": 83, "z": 106, "block": "minecraft:dark_oak_stairs[facing=north,half=bottom]"}, {"x": 107, "y": 83, "z": 102, "block": "minecraft:dark_oak_stairs[facing=south,half=bottom]"}, {"x": 107, "y": 83, "z": 106, "block": "minecraft:dark_oak_stairs[facing=north,half=bottom]"}, {"x": 100, "y": 83, "z": 103, "block": "minecraft:oak_planks"}, {"x": 100, "y": 83, "z": 104, "block": "minecraft:oak_planks"}, {"x": 100, "y": 83, "z": 105, "block": "minecraft:oak_planks"}, {"x": 106, "y": 83, "z": 103, "block": "minecraft:oak_planks"}, {"x": 106, "y": 83, "z": 104, "block": "minecraft:oak_planks"}, {"x": 106, "y": 83, "z": 105, "block": "minecraft:oak_planks"}, {"x": 99, "y": 84, "z": 103, "block": "minecraft:dark_oak_stairs[facing=south,half=bottom]"}, {"x": 99, "y": 84, "z": 105, "block": "minecraft:dark_oak_stairs[facing=north,half=bottom]"}, {"x": 100, "y": 84, "z": 103, "block": "minecraft:dark_oak_stairs[facing=south,half=bottom]"}, {"x": 100, "y": 84, "z": 105, "block": "minecraft:dark_oak_stairs[facing=north,half=bottom]"}, {"x": 101, "y": 84, "z": 103, "block": "minecraft:dark_oak_stairs[facing=south,half=bottom]"}, {"x": 101, "y": 84, "z": 105, "block": "minecraft:dark_oak_stairs[facing=north,half=bottom]"}, {"x": 102, "y": 84, "z": 103, "block": "minecraft:dark_oak_stairs[facing=south,half=bottom]"}, {"x": 102, "y": 84, "z": 105, "block": "minecraft:dark_oak_stairs[facing=north,half=bottom]"}, {"x": 103, "y": 84, "z": 103, "block": "minecraft:dark_oak_stairs[facing=south,half=bottom]"}, {"x": 103, "y": 84, "z": 105, "block": "minecraft:dark_oak_stairs[facing=north,half=bottom]"}, {"x": 104, "y": 84, "z": 103, "block": "minecraft:dark_oak_stairs[facing=south,half=bottom]"}, {"x": 104, "y": 84, "z": 105, "block": "minecraft:dark_oak_stairs[facing=north,half=bottom]"}, {"x": 105, "y": 84, "z": 103, "block": "minecraft:dark_oak_stairs[facing=south,half=bottom]"}, {"x": 105, "y": 84, "z": 105, "block": "minecraft:dark_oak_stairs[facing=north,half=bottom]"}, {"x": 106, "y": 84, "z": 103, "block": "minecraft:dark_oak_stairs[facing=south,half=bottom]"}, {"x": 106, "y": 84, "z": 105, "block": "minecraft:dark_oak_stairs[facing=north,half=bottom]"}, {"x": 107, "y": 84, "z": 103, "block": "minecraft:dark_oak_stairs[facing=south,half=bottom]"}, {"x": 107, "y": 84, "z": 105, "block": "minecraft:dark_oak_stairs[facing=north,half=bottom]"}, {"x": 100, "y": 84, "z": 104, "block": "minecraft:oak_planks"}, {"x": 106, "y": 84, "z": 104, "block": "minecraft:oak_planks"}, {"x": 99, "y": 84, "z": 104, "block": "minecraft:spruce_planks"}, {"x": 99, "y": 85, "z": 104, "block": "minecraft:dark_oak_slab[type=top]"}, {"x": 100, "y": 84, "z": 104, "block": "minecraft:spruce_planks"}, {"x": 100, "y": 85, "z": 104, "block": "minecraft:dark_oak_slab[type=top]"}, {"x": 101, "y": 84, "z": 104, "block": "minecraft:spruce_planks"}, {"x": 101, "y": 85, "z": 104, "block": "minecraft:dark_oak_slab[type=top]"}, {"x": 102, "y": 84, "z": 104, "block": "minecraft:spruce_planks"}, {"x": 102, "y": 85, "z": 104, "block": "minecraft:dark_oak_slab[type=top]"}, {"x": 103, "y": 84, "z": 104, "block": "minecraft:spruce_planks"}, {"x": 103, "y": 85, "z": 104, "block": "minecraft:dark_oak_slab[type=top]"}, {"x": 104, "y": 84, "z": 104, "block": "minecraft:spruce_planks"}, {"x": 104, "y": 85, "z": 104, "block": "minecraft:dark_oak_slab[type=top]"}, {"x": 105, "y": 84, "z": 104, "block": "minecraft:spruce_planks"}, {"x": 105, "y": 85, "z": 104, "block": "minecraft:dark_oak_slab[type=top]"}, {"x": 106, "y": 84, "z": 104, "block": "minecraft:spruce_planks"}, {"x": 106, "y": 85, "z": 104, "block": "minecraft:dark_oak_slab[type=top]"}, {"x": 107, "y": 84, "z": 104, "block": "minecraft:spruce_planks"}, {"x": 107, "y": 85, "z": 104, "block": "minecraft:dark_oak_slab[type=top]"}, {"x": 98, "y": 80, "z": 99, "block": "minecraft:dark_oak_trapdoor[facing=east,half=bottom,open=true]"}, {"x": 98, "y": 80, "z": 109, "block": "minecraft:dark_oak_trapdoor[facing=east,half=bottom,open=true]"}, {"x": 99, "y": 79, "z": 99, "block": "minecraft:dark_oak_stairs[facing=north,half=top]"}, {"x": 99, "y": 79, "z": 109, "block": "minecraft:dark_oak_stairs[facing=south,half=top]"}, {"x": 99, "y": 80, "z": 98, "block": "minecraft:dark_oak_trapdoor[facing=south,half=bottom,open=true]"}, {"x": 99, "y": 80, "z": 110, "block": "minecraft:dark_oak_trapdoor[facing=north,half=bottom,open=true]"}, {"x": 100, "y": 80, "z": 98, "block": "minecraft:dark_oak_trapdoor[facing=south,half=bottom,open=true]"}, {"x": 100, "y": 80, "z": 110, "block": "minecraft:dark_oak_trapdoor[facing=north,half=bottom,open=true]"}, {"x": 101, "y": 79, "z": 99, "block": "minecraft:dark_oak_stairs[facing=north,half=top]"}, {"x": 101, "y": 79, "z": 109, "block": "minecraft:dark_oak_stairs[facing=south,half=top]"}, {"x": 101, "y": 80, "z": 98, "block": "minecraft:dark_oak_trapdoor[facing=south,half=bottom,open=true]"}, {"x": 101, "y": 80, "z": 110, "block": "minecraft:dark_oak_trapdoor[facing=north,half=bottom,open=true]"}, {"x": 102, "y": 80, "z": 98, "block": "minecraft:dark_oak_trapdoor[facing=south,half=bottom,open=true]"}, {"x": 102, "y": 80, "z": 110, "block": "minecraft:dark_oak_trapdoor[facing=north,half=bottom,open=true]"}, {"x": 103, "y": 79, "z": 99, "block": "minecraft:dark_oak_stairs[facing=north,half=top]"}, {"x": 103, "y": 79, "z": 109, "block": "minecraft:dark_oak_stairs[facing=south,half=top]"}, {"x": 103, "y": 80, "z": 98, "block": "minecraft:dark_oak_trapdoor[facing=south,half=bottom,open=true]"}, {"x": 103, "y": 80, "z": 110, "block": "minecraft:dark_oak_trapdoor[facing=north,half=bottom,open=true]"}, {"x": 104, "y": 80, "z": 98, "block": "minecraft:dark_oak_trapdoor[facing=south,half=bottom,open=true]"}, {"x": 104, "y": 80, "z": 110, "block": "minecraft:dark_oak_trapdoor[facing=north,half=bottom,open=true]"}, {"x": 105, "y": 79, "z": 99, "block": "minecraft:dark_oak_stairs[facing=north,half=top]"}, {"x": 105, "y": 79, "z": 109, "block": "minecraft:dark_oak_stairs[facing=south,half=top]"}, {"x": 105, "y": 80, "z": 98, "block": "minecraft:dark_oak_trapdoor[facing=south,half=bottom,open=true]"}, {"x": 105, "y": 80, "z": 110, "block": "minecraft:dark_oak_trapdoor[facing=north,half=bottom,open=true]"}, {"x": 106, "y": 80, "z": 98, "block": "minecraft:dark_oak_trapdoor[facing=south,half=bottom,open=true]"}, {"x": 106, "y": 80, "z": 110, "block": "minecraft:dark_oak_trapdoor[facing=north,half=bottom,open=true]"}, {"x": 107, "y": 79, "z": 99, "block": "minecraft:dark_oak_stairs[facing=north,half=top]"}, {"x": 107, "y": 79, "z": 109, "block": "minecraft:dark_oak_stairs[facing=south,half=top]"}, {"x": 107, "y": 80, "z": 98, "block": "minecraft:dark_oak_trapdoor[facing=south,half=bottom,open=true]"}, {"x": 107, "y": 80, "z": 110, "block": "minecraft:dark_oak_trapdoor[facing=north,half=bottom,open=true]"}, {"x": 108, "y": 80, "z": 99, "block": "minecraft:dark_oak_trapdoor[facing=west,half=bottom,open=true]"}, {"x": 108, "y": 80, "z": 109, "block": "minecraft:dark_oak_trapdoor[facing=west,half=bottom,open=true]"}]}