{"blocks": [{"x": 99, "y": 80, "z": 99, "block": "minecraft:deepslate_tile_stairs[facing=south,half=bottom,shape=outer_left]"}, {"x": 99, "y": 80, "z": 107, "block": "minecraft:deepslate_tile_stairs[facing=north,half=bottom,shape=outer_right]"}, {"x": 100, "y": 80, "z": 99, "block": "minecraft:deepslate_tile_stairs[facing=south,half=bottom]"}, {"x": 100, "y": 80, "z": 107, "block": "minecraft:deepslate_tile_stairs[facing=north,half=bottom]"}, {"x": 101, "y": 80, "z": 99, "block": "minecraft:deepslate_tile_stairs[facing=south,half=bottom]"}, {"x": 101, "y": 80, "z": 107, "block": "minecraft:deepslate_tile_stairs[facing=north,half=bottom]"}, {"x": 102, "y": 80, "z": 99, "block": "minecraft:deepslate_tile_stairs[facing=south,half=bottom]"}, {"x": 102, "y": 80, "z": 107, "block": "minecraft:deepslate_tile_stairs[facing=north,half=bottom]"}, {"x": 103, "y": 80, "z": 99, "block": "minecraft:deepslate_tile_stairs[facing=south,half=bottom]"}, {"x": 103, "y": 80, "z": 107, "block": "minecraft:deepslate_tile_stairs[facing=north,half=bottom]"}, {"x": 104, "y": 80, "z": 99, "block": "minecraft:deepslate_tile_stairs[facing=south,half=bottom]"}, {"x": 104, "y": 80, "z": 107, "block": "minecraft:deepslate_tile_stairs[facing=north,half=bottom]"}, {"x": 105, "y": 80, "z": 99, "block": "minecraft:deepslate_tile_stairs[facing=south,half=bottom]"}, {"x": 105, "y": 80, "z": 107, "block": "minecraft:deepslate_tile_stairs[facing=north,half=bottom]"}, {"x": 106, "y": 80, "z": 99, "block": "minecraft:deepslate_tile_stairs[facing=south,half=bottom]"}, {"x": 106, "y": 80, "z": 107, "block": "minecraft:deepslate_tile_stairs[facing=north,half=bottom]"}, {"x": 107, "y": 80, "z": 99, "block": "minecraft:deepslate_tile_stairs[facing=south,half=bottom]"}, {"x": 107, "y": 80, "z": 107, "block": "minecraft:deepslate_tile_stairs[facing=north,half=bottom]"}, {"x": 108, "y": 80, "z": 99, "block": "minecraft:deepslate_tile_stairs[facing=south,half=bottom]"}, {"x": 108, "y": 80, "z": 107, "block": "minecraft:deepslate_tile_stairs[facing=north,half=bottom]"}, {"x": 109, "y": 80, "z": 99, "block": "minecraft:deepslate_tile_stairs[facing=south,half=bottom,shape=outer_right]"}, {"x": 109, "y": 80, "z": 107, "block": "minecraft:deepslate_tile_stairs[facing=north,half=bottom,shape=outer_left]"}, {"x": 99, "y": 80, "z": 100, "block": "minecraft:deepslate_tile_stairs[facing=east,half=bottom]"}, {"x": 109, "y": 80, "z": 100, "block": "minecraft:deepslate_tile_stairs[facing=west,half=bottom]"}, {"x": 99, "y": 80, "z": 101, "block": "minecraft:deepslate_tile_stairs[facing=east,half=bottom]"}, {"x": 109, "y": 80, "z": 101, "block": "minecraft:deepslate_tile_stairs[facing=west,half=bottom]"}, {"x": 99, "y": 80, "z": 102, "block": "minecraft:deepslate_tile_stairs[facing=east,half=bottom]"}, {"x": 109, "y": 80, "z": 102, "block": "minecraft:deepslate_tile_stairs[facing=west,half=bottom]"}, {"x": 99, "y": 80, "z": 103, "block": "minecraft:deepslate_tile_stairs[facing=east,half=bottom]"}, {"x": 109, "y": 80, "z": 103, "block": "minecraft:deepslate_tile_stairs[facing=west,half=bottom]"}, {"x": 99, "y": 80, "z": 104, "block": "minecraft:deepslate_tile_stairs[facing=east,half=bottom]"}, {"x": 109, "y": 80, "z": 104, "block": "minecraft:deepslate_tile_stairs[facing=west,half=bottom]"}, {"x": 99, "y": 80, "z": 105, "block": "minecraft:deepslate_tile_stairs[facing=east,half=bottom]"}, {"x": 109, "y": 80, "z": 105, "block": "minecraft:deepslate_tile_stairs[facing=west,half=bottom]"}, {"x": 99, "y": 80, "z": 106, "block": "minecraft:deepslate_tile_stairs[facing=east,half=bottom]"}, {"x": 109, "y": 80, "z": 106, "block": "minecraft:deepslate_tile_stairs[facing=west,half=bottom]"}, {"x": 100, "y": 81, "z": 100, "block": "minecraft:deepslate_tile_stairs[facing=south,half=bottom,shape=outer_left]"}, {"x": 100, "y": 81, "z": 106, "block": "minecraft:deepslate_tile_stairs[facing=north,half=bottom,shape=outer_right]"}, {"x": 101, "y": 81, "z": 100, "block": "minecraft:deepslate_tile_stairs[facing=south,half=bottom]"}, {"x": 101, "y": 81, "z": 106, "block": "minecraft:deepslate_tile_stairs[facing=north,half=bottom]"}, {"x": 102, "y": 81, "z": 100, "block": "minecraft:deepslate_tile_stairs[facing=south,half=bottom]"}, {"x": 102, "y": 81, "z": 106, "block": "minecraft:deepslate_tile_stairs[facing=north,half=bottom]"}, {"x": 103, "y": 81, "z": 100, "block": "minecraft:deepslate_tile_stairs[facing=south,half=bottom]"}, {"x": 103, "y": 81, "z": 106, "block": "minecraft:deepslate_tile_stairs[facing=north,half=bottom]"}, {"x": 104, "y": 81, "z": 100, "block": "minecraft:deepslate_tile_stairs[facing=south,half=bottom]"}, {"x": 104, "y": 81, "z": 106, "block": "minecraft:deepslate_tile_stairs[facing=north,half=bottom]"}, {"x": 105, "y": 81, "z": 100, "block": "minecraft:deepslate_tile_stairs[facing=south,half=bottom]"}, {"x": 105, "y": 81, "z": 106, "block": "minecraft:deepslate_tile_stairs[facing=north,half=bottom]"}, {"x": 106, "y": 81, "z": 100, "block": "minecraft:deepslate_tile_stairs[facing=south,half=bottom]"}, {"x": 106, "y": 81, "z": 106, "block": "minecraft:deepslate_tile_stairs[facing=north,half=bottom]"}, {"x": 107, "y": 81, "z": 100, "block": "minecraft:deepslate_tile_stairs[facing=south,half=bottom]"}, {"x": 107, "y": 81, "z": 106, "block": "minecraft:deepslate_tile_stairs[facing=north,half=bottom]"}, {"x": 108, "y": 81, "z": 100, "block": "minecraft:deepslate_tile_stairs[facing=south,half=bottom,shape=outer_right]"}, {"x": 108, "y": 81, "z": 106, "block": "minecraft:deepslate_tile_stairs[facing=north,half=bottom,shape=outer_left]"}, {"x": 100, "y": 81, "z": 101, "block": "minecraft:deepslate_tile_stairs[facing=east,half=bottom]"}, {"x": 108, "y": 81, "z": 101, "block": "minecraft:deepslate_tile_stairs[facing=west,half=bottom]"}, {"x": 100, "y": 81, "z": 102, "block": "minecraft:deepslate_tile_stairs[facing=east,half=bottom]"}, {"x": 108, "y": 81, "z": 102, "block": "minecraft:deepslate_tile_stairs[facing=west,half=bottom]"}, {"x": 100, "y": 81, "z": 103, "block": "minecraft:deepslate_tile_stairs[facing=east,half=bottom]"}, {"x": 108, "y": 81, "z": 103, "block": "minecraft:deepslate_tile_stairs[facing=west,half=bottom]"}, {"x": 100, "y": 81, "z": 104, "block": "minecraft:deepslate_tile_stairs[facing=east,half=bottom]"}, {"x": 108, "y": 81, "z": 104, "block": "minecraft:deepslate_tile_stairs[facing=west,half=bottom]"}, {"x": 100, "y": 81, "z": 105, "block": "minecraft:deepslate_tile_stairs[facing=east,half=bottom]"}, {"x": 108, "y": 81, "z": 105, "block": "minecraft:deepslate_tile_stairs[facing=west,half=bottom]"}, {"x": 101, "y": 82, "z": 101, "block": "minecraft:deepslate_tile_stairs[facing=south,half=bottom,shape=outer_left]"}, {"x": 101, "y": 82, "z": 105, "block": "minecraft:deepslate_tile_stairs[facing=north,half=bottom,shape=outer_right]"}, {"x": 102, "y": 82, "z": 101, "block": "minecraft:deepslate_tile_stairs[facing=south,half=bottom]"}, {"x": 102, "y": 82, "z": 105, "block": "minecraft:deepslate_tile_stairs[facing=north,half=bottom]"}, {"x": 103, "y": 82, "z": 101, "block": "minecraft:deepslate_tile_stairs[facing=south,half=bottom]"}, {"x": 103, "y": 82, "z": 105, "block": "minecraft:deepslate_tile_stairs[facing=north,half=bottom]"}, {"x": 104, "y": 82, "z": 101, "block": "minecraft:deepslate_tile_stairs[facing=south,half=bottom]"}, {"x": 104, "y": 82, "z": 105, "block": "minecraft:deepslate_tile_stairs[facing=north,half=bottom]"}, {"x": 105, "y": 82, "z": 101, "block": "minecraft:deepslate_tile_stairs[facing=south,half=bottom]"}, {"x": 105, "y": 82, "z": 105, "block": "minecraft:deepslate_tile_stairs[facing=north,half=bottom]"}, {"x": 106, "y": 82, "z": 101, "block": "minecraft:deepslate_tile_stairs[facing=south,half=bottom]"}, {"x": 106, "y": 82, "z": 105, "block": "minecraft:deepslate_tile_stairs[facing=north,half=bottom]"}, {"x": 107, "y": 82, "z": 101, "block": "minecraft:deepslate_tile_stairs[facing=south,half=bottom,shape=outer_right]"}, {"x": 107, "y": 82, "z": 105, "block": "minecraft:deepslate_tile_stairs[facing=north,half=bottom,shape=outer_left]"}, {"x": 101, "y": 82, "z": 102, "block": "minecraft:deepslate_tile_stairs[facing=east,half=bottom]"}, {"x": 107, "y": 82, "z": 102, "block": "minecraft:deepslate_tile_stairs[facing=west,half=bottom]"}, {"x": 101, "y": 82, "z": 103, "block": "minecraft:deepslate_tile_stairs[facing=east,half=bottom]"}, {"x": 107, "y": 82, "z": 103, "block": "minecraft:deepslate_tile_stairs[facing=west,half=bottom]"}, {"x": 101, "y": 82, "z": 104, "block": "minecraft:deepslate_tile_stairs[facing=east,half=bottom]"}, {"x": 107, "y": 82, "z": 104, "block": "minecraft:deepslate_tile_stairs[facing=west,half=bottom]"}, {"x": 102, "y": 83, "z": 102, "block": "minecraft:deepslate_tile_stairs[facing=south,half=bottom,shape=outer_left]"}, {"x": 102, "y": 83, "z": 104, "block": "minecraft:deepslate_tile_stairs[facing=north,half=bottom,shape=outer_right]"}, {"x": 103, "y": 83, "z": 102, "block": "minecraft:deepslate_tile_stairs[facing=south,half=bottom]"}, {"x": 103, "y": 83, "z": 104, "block": "minecraft:deepslate_tile_stairs[facing=north,half=bottom]"}, {"x": 104, "y": 83, "z": 102, "block": "minecraft:deepslate_tile_stairs[facing=south,half=bottom]"}, {"x": 104, "y": 83, "z": 104, "block": "minecraft:deepslate_tile_stairs[facing=north,half=bottom]"}, {"x": 105, "y": 83, "z": 102, "block": "minecraft:deepslate_tile_stairs[facing=south,half=bottom]"}, {"x": 105, "y": 83, "z": 104, "block": "minecraft:deepslate_tile_stairs[facing=north,half=bottom]"}, {"x": 106, "y": 83, "z": 102, "block": "minecraft:deepslate_tile_stairs[facing=south,half=bottom,shape=outer_right]"}, {"x": 106, "y": 83, "z": 104, "block": "minecraft:deepslate_tile_stairs[facing=north,half=bottom,shape=outer_left]"}, {"x": 102, "y": 83, "z": 103, "block": "minecraft:deepslate_tile_stairs[facing=east,half=bottom]"}, {"x": 106, "y": 83, "z": 103, "block": "minecraft:deepslate_tile_stairs[facing=west,half=bottom]"}, {"x": 103, "y": 82, "z": 103, "block": "minecraft:deepslate_tiles"}, {"x": 103, "y": 83, "z": 103, "block": "minecraft:deepslate_tile_slab[type=top]"}, {"x": 104, "y": 82, "z": 103, "block": "minecraft:deepslate_tiles"}, {"x": 104, "y": 83, "z": 103, "block": "minecraft:deepslate_tile_slab[type=top]"}, {"x": 105, "y": 82, "z": 103, "block": "minecraft:deepslate_tiles"}, {"x": 105, "y": 83, "z": 103, "block": "minecraft:deepslate_tile_slab[type=top]"}]}
